{
	"id": "CVE-2019-10856",
	"vulnerabilities": [
		{
			"content": {
				"id": "CVE-2019-10856",
				"description": "In Jupyter Notebook before 5.7.8, an open redirect can occur via an empty netloc. This issue exists because of an incomplete fix for CVE-2019-10255.",
				"severity": [
					{
						"type": "cvss_v2",
						"source": "nvd@nist.gov",
						"cvss_v2": {
							"vector": "AV:N/AC:M/Au:N/C:P/I:P/A:N",
							"base_score": 5.8,
							"nvd_base_severity": "MEDIUM",
							"temporal_score": 5.8,
							"nvd_temporal_severity": "MEDIUM",
							"environmental_score": 5.8,
							"nvd_environmental_severity": "MEDIUM"
						}
					},
					{
						"type": "cvss_v30",
						"source": "nvd@nist.gov",
						"cvss_v30": {
							"vector": "CVSS:3.0/AV:N/AC:L/PR:N/UI:R/S:C/C:L/I:L/A:N",
							"base_score": 6.1,
							"base_severity": "MEDIUM",
							"temporal_score": 6.1,
							"temporal_severity": "MEDIUM",
							"environmental_score": 6.1,
							"environmental_severity": "MEDIUM"
						}
					}
				],
				"cwe": [
					{
						"source": "nvd@nist.gov",
						"cwe": [
							"CWE-601"
						]
					}
				],
				"references": [
					{
						"source": "cve@mitre.org",
						"url": "https://blog.jupyter.org/open-redirect-vulnerability-in-jupyter-jupyterhub-adf43583f1e4"
					},
					{
						"source": "cve@mitre.org",
						"url": "https://github.com/jupyter/notebook/compare/16cf97c...b8e30ea"
					},
					{
						"source": "nvd.nist.gov",
						"url": "https://nvd.nist.gov/vuln/detail/CVE-2019-10856"
					}
				],
				"published": "2019-04-04T16:29:03.29Z",
				"modified": "2019-04-05T19:45:59.383Z"
			},
			"segments": [
				{
					"ecosystem": "cpe"
				}
			]
		}
	],
	"detections": [
		{
			"ecosystem": "cpe",
			"conditions": [
				{
					"criteria": {
						"operator": "OR",
						"criterias": [
							{
								"operator": "OR",
								"criterias": [
									{
										"operator": "OR",
										"criterias": [
											{
												"operator": "OR",
												"criterions": [
													{
														"vulnerable": true,
														"fix_status": {
															"class": "unknown"
														},
														"package": {
															"cpe": "cpe:2.3:a:jupyter:notebook:*:*:*:*:*:*:*:*"
														},
														"affected": {
															"type": "semver",
															"range": [
																{
																	"lt": "5.7.8"
																}
															]
														}
													}
												]
											}
										]
									}
								]
							}
						]
					}
				}
			]
		}
	],
	"data_source": {
		"id": "nvd-api-cve",
		"raws": [
			"vuls-data-raw-nvd-api-cve/2019/CVE-2019-10856.json"
		]
	}
}
